<?xml version="1.0" encoding="utf-8"?>
<!-- This URDF was automatically created by SolidWorks to URDF Exporter! Originally created by Stephen Brawner (brawner@gmail.com) 
     Commit Version: 1.6.0-1-g15f4949  Build Version: 1.6.7594.29634
     For more information, please see http://wiki.ros.org/sw_urdf_exporter -->
<robot
  name="assem4.SLDASM">
  <link
    name="base_link">
    <inertial>
      <origin
        xyz="0.0882012329530626 -0.155190346120254 0.0673068296307817"
        rpy="0 0 0" />
      <mass
        value="0.690191118823633" />
      <inertia
        ixx="0.00182938745488933"
        ixy="5.95499076853132E-08"
        ixz="3.47473657537897E-09"
        iyy="0.000678749982914949"
        iyz="-7.90135375495565E-05"
        izz="0.00231218793666964" />
    </inertial>
    <visual>
      <origin
        xyz="0 0 0"
        rpy="0 0 0" />
      <geometry>
        <mesh
          filename="package://assem4.SLDASM/meshes/base_link.STL" />
      </geometry>
      <material
        name="">
        <color
          rgba="0.792156862745098 0.819607843137255 0.933333333333333 1" />
      </material>
    </visual>
    <collision>
      <origin
        xyz="0 0 0"
        rpy="0 0 0" />
      <geometry>
        <mesh
          filename="package://assem4.SLDASM/meshes/base_link.STL" />
      </geometry>
    </collision>
  </link>
  <link
    name="frontLeftLink">
    <inertial>
      <origin
        xyz="0.012273 -1.3878E-17 2.7756E-17"
        rpy="0 0 0" />
      <mass
        value="0.017128" />
      <inertia
        ixx="7.5345E-06"
        ixy="8.8233E-25"
        ixz="1.0588E-23"
        iyy="3.8586E-06"
        iyz="-2.3413E-23"
        izz="3.8586E-06" />
    </inertial>
    <visual>
      <origin
        xyz="0 0 0"
        rpy="0 0 0" />
      <geometry>
        <mesh
          filename="package://assem4.SLDASM/meshes/frontLeftLink.STL" />
      </geometry>
      <material
        name="">
        <color
          rgba="0.79216 0.81961 0.93333 1" />
      </material>
    </visual>
    <collision>
      <origin
        xyz="0 0 0"
        rpy="0 0 0" />
      <geometry>
        <mesh
          filename="package://assem4.SLDASM/meshes/frontLeftLink.STL" />
      </geometry>
    </collision>
  </link>
  <joint
    name="frontLeftWheel"
    type="continuous">
    <origin
      xyz="0.1301 -0.18988 0.067659"
      rpy="1.5708 0 0" />
    <parent
      link="base_link" />
    <child
      link="frontLeftLink" />
    <axis
      xyz="1 0 0" />
  </joint>
  <link
    name="frontRightLink">
    <inertial>
      <origin
        xyz="0.0044257 0 2.7756E-17"
        rpy="0 0 0" />
      <mass
        value="0.017128" />
      <inertia
        ixx="7.5345E-06"
        ixy="6.1763E-24"
        ixz="3.5293E-24"
        iyy="3.8586E-06"
        iyz="-6.8821E-23"
        izz="3.8586E-06" />
    </inertial>
    <visual>
      <origin
        xyz="0 0 0"
        rpy="0 0 0" />
      <geometry>
        <mesh
          filename="package://assem4.SLDASM/meshes/frontRightLink.STL" />
      </geometry>
      <material
        name="">
        <color
          rgba="0.79216 0.81961 0.93333 1" />
      </material>
    </visual>
    <collision>
      <origin
        xyz="0 0 0"
        rpy="0 0 0" />
      <geometry>
        <mesh
          filename="package://assem4.SLDASM/meshes/frontRightLink.STL" />
      </geometry>
    </collision>
  </link>
  <joint
    name="frontRightWheel"
    type="continuous">
    <origin
      xyz="0.030132 -0.18988 0.067659"
      rpy="1.5708 0 0" />
    <parent
      link="base_link" />
    <child
      link="frontRightLink" />
    <axis
      xyz="1 0 0" />
  </joint>
  <link
    name="backLeftLink">
    <inertial>
      <origin
        xyz="0.01359 1.3878E-17 0"
        rpy="0 0 0" />
      <mass
        value="0.017128" />
      <inertia
        ixx="7.5345E-06"
        ixy="-4.7754E-39"
        ixz="-1.0395E-38"
        iyy="3.8586E-06"
        iyz="9.4311E-40"
        izz="3.8586E-06" />
    </inertial>
    <visual>
      <origin
        xyz="0 0 0"
        rpy="0 0 0" />
      <geometry>
        <mesh
          filename="package://assem4.SLDASM/meshes/backLeftLink.STL" />
      </geometry>
      <material
        name="">
        <color
          rgba="0.79216 0.81961 0.93333 1" />
      </material>
    </visual>
    <collision>
      <origin
        xyz="0 0 0"
        rpy="0 0 0" />
      <geometry>
        <mesh
          filename="package://assem4.SLDASM/meshes/backLeftLink.STL" />
      </geometry>
    </collision>
  </link>
  <joint
    name="backLeftWheel"
    type="continuous">
    <origin
      xyz="0.12876 -0.10439 0.067659"
      rpy="1.5708 0 0" />
    <parent
      link="base_link" />
    <child
      link="backLeftLink" />
    <axis
      xyz="1 0 0" />
  </joint>
  <link
    name="backRightLink">
    <inertial>
      <origin
        xyz="0.004 -1.8041E-16 1.9429E-16"
        rpy="0 0 0" />
      <mass
        value="0.017128" />
      <inertia
        ixx="7.5345E-06"
        ixy="8.8233E-25"
        ixz="-1.4117E-23"
        iyy="3.8586E-06"
        iyz="-5.7674E-23"
        izz="3.8586E-06" />
    </inertial>
    <visual>
      <origin
        xyz="0 0 0"
        rpy="0 0 0" />
      <geometry>
        <mesh
          filename="package://assem4.SLDASM/meshes/backRightLink.STL" />
      </geometry>
      <material
        name="">
        <color
          rgba="0.79216 0.81961 0.93333 1" />
      </material>
    </visual>
    <collision>
      <origin
        xyz="0 0 0"
        rpy="0 0 0" />
      <geometry>
        <mesh
          filename="package://assem4.SLDASM/meshes/backRightLink.STL" />
      </geometry>
    </collision>
  </link>
  <joint
    name="backRightWheel"
    type="continuous">
    <origin
      xyz="0.030319 -0.10439 0.067659"
      rpy="1.5708 0 0" />
    <parent
      link="base_link" />
    <child
      link="backRightLink" />
    <axis
      xyz="1 0 0" />
  </joint>
</robot>